ERROR | 2015-11-19 23:29:40,521 | app |  log_exception | Exception on /createaccount [GET]
Traceback (most recent call last):
  File "/usr/local/lib/python2.7/site-packages/Flask-0.10.1-py2.7.egg/flask/app.py", line 1817, in wsgi_app
    response = self.full_dispatch_request()
  File "/usr/local/lib/python2.7/site-packages/Flask-0.10.1-py2.7.egg/flask/app.py", line 1477, in full_dispatch_request
    rv = self.handle_user_exception(e)
  File "/usr/local/lib/python2.7/site-packages/Flask-0.10.1-py2.7.egg/flask/app.py", line 1381, in handle_user_exception
    reraise(exc_type, exc_value, tb)
  File "/usr/local/lib/python2.7/site-packages/Flask-0.10.1-py2.7.egg/flask/app.py", line 1473, in full_dispatch_request
    rv = self.preprocess_request()
  File "/usr/local/lib/python2.7/site-packages/Flask-0.10.1-py2.7.egg/flask/app.py", line 1666, in preprocess_request
    rv = func()
  File "webapp.py", line 65, in before_request
    g.db = connect_db()
NameError: global name 'connect_db' is not defined
ERROR | 2015-11-19 23:29:44,601 | app |  log_exception | Exception on / [GET]
Traceback (most recent call last):
  File "/usr/local/lib/python2.7/site-packages/Flask-0.10.1-py2.7.egg/flask/app.py", line 1817, in wsgi_app
    response = self.full_dispatch_request()
  File "/usr/local/lib/python2.7/site-packages/Flask-0.10.1-py2.7.egg/flask/app.py", line 1477, in full_dispatch_request
    rv = self.handle_user_exception(e)
  File "/usr/local/lib/python2.7/site-packages/Flask-0.10.1-py2.7.egg/flask/app.py", line 1381, in handle_user_exception
    reraise(exc_type, exc_value, tb)
  File "/usr/local/lib/python2.7/site-packages/Flask-0.10.1-py2.7.egg/flask/app.py", line 1473, in full_dispatch_request
    rv = self.preprocess_request()
  File "/usr/local/lib/python2.7/site-packages/Flask-0.10.1-py2.7.egg/flask/app.py", line 1666, in preprocess_request
    rv = func()
  File "webapp.py", line 65, in before_request
    g.db = connect_db()
NameError: global name 'connect_db' is not defined
ERROR | 2015-11-19 23:29:52,897 | app |  log_exception | Exception on / [GET]
Traceback (most recent call last):
  File "/usr/local/lib/python2.7/site-packages/Flask-0.10.1-py2.7.egg/flask/app.py", line 1817, in wsgi_app
    response = self.full_dispatch_request()
  File "/usr/local/lib/python2.7/site-packages/Flask-0.10.1-py2.7.egg/flask/app.py", line 1477, in full_dispatch_request
    rv = self.handle_user_exception(e)
  File "/usr/local/lib/python2.7/site-packages/Flask-0.10.1-py2.7.egg/flask/app.py", line 1381, in handle_user_exception
    reraise(exc_type, exc_value, tb)
  File "/usr/local/lib/python2.7/site-packages/Flask-0.10.1-py2.7.egg/flask/app.py", line 1473, in full_dispatch_request
    rv = self.preprocess_request()
  File "/usr/local/lib/python2.7/site-packages/Flask-0.10.1-py2.7.egg/flask/app.py", line 1666, in preprocess_request
    rv = func()
  File "webapp.py", line 65, in before_request
    g.db = connect_db()
NameError: global name 'connect_db' is not defined
ERROR | 2015-11-19 23:38:11,596 | app |  log_exception | Exception on / [GET]
Traceback (most recent call last):
  File "/usr/local/lib/python2.7/site-packages/Flask-0.10.1-py2.7.egg/flask/app.py", line 1817, in wsgi_app
    response = self.full_dispatch_request()
  File "/usr/local/lib/python2.7/site-packages/Flask-0.10.1-py2.7.egg/flask/app.py", line 1477, in full_dispatch_request
    rv = self.handle_user_exception(e)
  File "/usr/local/lib/python2.7/site-packages/Flask-0.10.1-py2.7.egg/flask/app.py", line 1381, in handle_user_exception
    reraise(exc_type, exc_value, tb)
  File "/usr/local/lib/python2.7/site-packages/Flask-0.10.1-py2.7.egg/flask/app.py", line 1473, in full_dispatch_request
    rv = self.preprocess_request()
  File "/usr/local/lib/python2.7/site-packages/Flask-0.10.1-py2.7.egg/flask/app.py", line 1666, in preprocess_request
    rv = func()
  File "webapp.py", line 68, in before_request
    g.db = connect_db()
  File "webapp.py", line 50, in connect_db
    return sqlite3.connect(app.config['database'])
OperationalError: unable to open database file
ERROR | 2015-11-19 23:44:50,225 | app |  log_exception | Exception on / [GET]
Traceback (most recent call last):
  File "/usr/local/lib/python2.7/site-packages/Flask-0.10.1-py2.7.egg/flask/app.py", line 1817, in wsgi_app
    response = self.full_dispatch_request()
  File "/usr/local/lib/python2.7/site-packages/Flask-0.10.1-py2.7.egg/flask/app.py", line 1477, in full_dispatch_request
    rv = self.handle_user_exception(e)
  File "/usr/local/lib/python2.7/site-packages/Flask-0.10.1-py2.7.egg/flask/app.py", line 1381, in handle_user_exception
    reraise(exc_type, exc_value, tb)
  File "/usr/local/lib/python2.7/site-packages/Flask-0.10.1-py2.7.egg/flask/app.py", line 1473, in full_dispatch_request
    rv = self.preprocess_request()
  File "/usr/local/lib/python2.7/site-packages/Flask-0.10.1-py2.7.egg/flask/app.py", line 1666, in preprocess_request
    rv = func()
  File "webapp.py", line 68, in before_request
    g.db = connect_db()
  File "webapp.py", line 50, in connect_db
    return sqlite3.connect(app.config['database'])
OperationalError: unable to open database file
ERROR | 2015-11-19 23:50:00,643 | app |  log_exception | Exception on / [GET]
Traceback (most recent call last):
  File "/usr/local/lib/python2.7/site-packages/Flask-0.10.1-py2.7.egg/flask/app.py", line 1817, in wsgi_app
    response = self.full_dispatch_request()
  File "/usr/local/lib/python2.7/site-packages/Flask-0.10.1-py2.7.egg/flask/app.py", line 1477, in full_dispatch_request
    rv = self.handle_user_exception(e)
  File "/usr/local/lib/python2.7/site-packages/Flask-0.10.1-py2.7.egg/flask/app.py", line 1381, in handle_user_exception
    reraise(exc_type, exc_value, tb)
  File "/usr/local/lib/python2.7/site-packages/Flask-0.10.1-py2.7.egg/flask/app.py", line 1473, in full_dispatch_request
    rv = self.preprocess_request()
  File "/usr/local/lib/python2.7/site-packages/Flask-0.10.1-py2.7.egg/flask/app.py", line 1666, in preprocess_request
    rv = func()
  File "webapp.py", line 68, in before_request
    g.db = connect_db()
  File "webapp.py", line 50, in connect_db
    return sqlite3.connect(app.config['database'])
OperationalError: unable to open database file
ERROR | 2015-11-19 23:50:06,236 | app |  log_exception | Exception on / [GET]
Traceback (most recent call last):
  File "/usr/local/lib/python2.7/site-packages/Flask-0.10.1-py2.7.egg/flask/app.py", line 1817, in wsgi_app
    response = self.full_dispatch_request()
  File "/usr/local/lib/python2.7/site-packages/Flask-0.10.1-py2.7.egg/flask/app.py", line 1477, in full_dispatch_request
    rv = self.handle_user_exception(e)
  File "/usr/local/lib/python2.7/site-packages/Flask-0.10.1-py2.7.egg/flask/app.py", line 1381, in handle_user_exception
    reraise(exc_type, exc_value, tb)
  File "/usr/local/lib/python2.7/site-packages/Flask-0.10.1-py2.7.egg/flask/app.py", line 1473, in full_dispatch_request
    rv = self.preprocess_request()
  File "/usr/local/lib/python2.7/site-packages/Flask-0.10.1-py2.7.egg/flask/app.py", line 1666, in preprocess_request
    rv = func()
  File "webapp.py", line 68, in before_request
    g.db = connect_db()
  File "webapp.py", line 50, in connect_db
    return sqlite3.connect(app.config['database'])
OperationalError: unable to open database file
ERROR | 2015-11-21 00:20:09,241 | app |  log_exception | Exception on /login [GET]
Traceback (most recent call last):
  File "/usr/local/lib/python2.7/site-packages/Flask-0.10.1-py2.7.egg/flask/app.py", line 1817, in wsgi_app
    response = self.full_dispatch_request()
  File "/usr/local/lib/python2.7/site-packages/Flask-0.10.1-py2.7.egg/flask/app.py", line 1477, in full_dispatch_request
    rv = self.handle_user_exception(e)
  File "/usr/local/lib/python2.7/site-packages/Flask-0.10.1-py2.7.egg/flask/app.py", line 1381, in handle_user_exception
    reraise(exc_type, exc_value, tb)
  File "/usr/local/lib/python2.7/site-packages/Flask-0.10.1-py2.7.egg/flask/app.py", line 1475, in full_dispatch_request
    rv = self.dispatch_request()
  File "/usr/local/lib/python2.7/site-packages/Flask-0.10.1-py2.7.egg/flask/app.py", line 1461, in dispatch_request
    return self.view_functions[rule.endpoint](**req.view_args)
  File "webapp.py", line 270, in login
    testname = query_db(query, [request.form['username']])
NameError: global name 'query_db' is not defined
ERROR | 2015-11-21 00:23:47,514 | app |  log_exception | Exception on /createaccount [POST]
Traceback (most recent call last):
  File "/usr/local/lib/python2.7/site-packages/Flask-0.10.1-py2.7.egg/flask/app.py", line 1817, in wsgi_app
    response = self.full_dispatch_request()
  File "/usr/local/lib/python2.7/site-packages/Flask-0.10.1-py2.7.egg/flask/app.py", line 1477, in full_dispatch_request
    rv = self.handle_user_exception(e)
  File "/usr/local/lib/python2.7/site-packages/Flask-0.10.1-py2.7.egg/flask/app.py", line 1381, in handle_user_exception
    reraise(exc_type, exc_value, tb)
  File "/usr/local/lib/python2.7/site-packages/Flask-0.10.1-py2.7.egg/flask/app.py", line 1475, in full_dispatch_request
    rv = self.dispatch_request()
  File "/usr/local/lib/python2.7/site-packages/Flask-0.10.1-py2.7.egg/flask/app.py", line 1461, in dispatch_request
    return self.view_functions[rule.endpoint](**req.view_args)
  File "webapp.py", line 256, in createaccount
    flash('Your account was successfully created!')
  File "/usr/local/lib/python2.7/site-packages/Flask-0.10.1-py2.7.egg/flask/helpers.py", line 366, in flash
    session['_flashes'] = flashes
  File "/usr/local/lib/python2.7/site-packages/Werkzeug-0.11.2-py2.7.egg/werkzeug/local.py", line 345, in __setitem__
    self._get_current_object()[key] = value
  File "/usr/local/lib/python2.7/site-packages/Flask-0.10.1-py2.7.egg/flask/sessions.py", line 126, in _fail
    raise RuntimeError('the session is unavailable because no secret '
RuntimeError: the session is unavailable because no secret key was set.  Set the secret_key on the application to something unique and secret.
